<?xml version="1.0" ?>
<!-- =================================================================================== -->
<!-- |    This document was autogenerated by xacro from install/robotnik_description/share/robotnik_description/robots/rbkairos/rbkairos.urdf.xacro | -->
<!-- |    EDITING THIS FILE BY HAND IS NOT RECOMMENDED                                 | -->
<!-- =================================================================================== -->

<robot name="rbkairos" xmlns:gz="http://gazebosim.org/schema">
  <!-- This file unifies all sensors that can be used on simulation, defined as xacro:macros -->
  <!-- source en.wikipedia.org/wiki/List_of_moments_of_inertia-->
  <!-- $(find robotnik_sensors_gazebo)/config/camera/axis_m5013.yaml -->
  <!-- $(find robotnik_sensors_gazebo)/config/camera/axis_m5074.yaml-->
  <!-- $(find robotnik_sensors_gazebo)/config/camera/axis_m5525.yaml -->
  <!-- $(find robotnik_sensors_gazebo)/config/camera/axis_m5526.yaml-->
  <!-- $(find robotnik_sensors_gazebo)/config/camera/link_750_nh.yaml -->
  <!-- Robot mechanical and motor parameters -->
  <!-- BASE FOOTPRINT -->
  <link name="base_footprint">
    <visual>
      <origin rpy="0 0 0" xyz="0 0 0"/>
      <geometry>
        <box size="0.001 0.001 0.001"/>
      </geometry>
    </visual>
  </link>
  <joint name="base_footprint_joint" type="fixed">
    <origin rpy="0 0 0" xyz="0 0 0.127"/>
    <!-- ${wheel_radius} property must be defined inside wheel description -->
    <parent link="base_footprint"/>
    <child link="base_link"/>
  </joint>
  <!-- BASE_LINK -->
  <link name="base_link">
    <inertial>
      <mass value="125.0"/>
      <origin xyz="0 0 0"/>
      <inertia ixx="1.391" ixy="0.004" ixz="0.0" iyy="6.853" iyz="0.0" izz="6.125"/>
    </inertial>
    <visual>
      <origin rpy="0 0 0" xyz="0 0 0"/>
      <geometry>
        <mesh filename="package://robotnik_description/meshes/bases/rbkairos/rbkairos_chassis.stl"/>
      </geometry>
      <material name="black">
        <color rgba="0.0 0.0 0.0 1"/>
      </material>
    </visual>
    <collision>
      <origin rpy="0 0 0 " xyz="0 0 0"/>
      <geometry>
        <mesh filename="package://robotnik_description/meshes/bases/rbkairos/rbkairos_chassis.stl"/>
      </geometry>
    </collision>
  </link>
  <gazebo reference="base_link">
    <material>Gazebo/Black</material>
  </gazebo>
  <!-- TOP COVER -->
  <link name="top_cover">
    <visual>
      <origin rpy="0 0 0" xyz="0 0 0.0065"/>
      <geometry>
        <mesh filename="package://robotnik_description/meshes/bases/rbkairos/rbkairos_top_cover.stl"/>
      </geometry>
      <material name="darkgrey">
        <color rgba="0.5 0.5 0.5 1"/>
      </material>
    </visual>
  </link>
  <joint name="top_cover_joint" type="fixed">
    <origin rpy="0 0 0" xyz="0.0 0 0.56162"/>
    <parent link="base_link"/>
    <child link="top_cover"/>
  </joint>
  <!-- LOGO ROBOTNIK LEFT -->
  <link name="base_logo_left">
    <visual>
      <origin rpy="0 0 0" xyz="0 0 0"/>
      <geometry>
        <mesh filename="package://robotnik_description/meshes/bases/robotnik_logo_chasis.stl"/>
      </geometry>
      <material name="darkgrey">
        <color rgba="0.5 0.5 0.5 1"/>
      </material>
    </visual>
  </link>
  <joint name="base_logo_left_joint" type="fixed">
    <origin rpy="0 0 0" xyz="0.0 0.2894 0.35562"/>
    <parent link="base_link"/>
    <child link="base_logo_left"/>
  </joint>
  <!-- LOGO ROBOTNIK RIGHT -->
  <link name="base_logo_right">
    <visual>
      <origin rpy="0 0 0" xyz="0 0 0"/>
      <geometry>
        <mesh filename="package://robotnik_description/meshes/bases/robotnik_logo_chasis.stl"/>
      </geometry>
      <material name="darkgrey">
        <color rgba="0.5 0.5 0.5 1"/>
      </material>
    </visual>
  </link>
  <joint name="base_logo_right_joint" type="fixed">
    <origin rpy="0 0 3.141592653589793" xyz="0.0 -0.28931 0.35562"/>
    <parent link="base_link"/>
    <child link="base_logo_right"/>
  </joint>
  <!-- LOGO ROBOTNIK FRONT -->
  <link name="base_logo_front">
    <visual>
      <origin rpy="0 0 0" xyz="0 0 0"/>
      <geometry>
        <mesh filename="package://robotnik_description/meshes/bases/robotnik_logo_chasis.stl"/>
      </geometry>
      <material name="darkgrey">
        <color rgba="0.5 0.5 0.5 1"/>
      </material>
    </visual>
  </link>
  <joint name="base_logo_front_joint" type="fixed">
    <origin rpy="0 0 -1.5707963267948966" xyz="0.345 0.0 0.0"/>
    <parent link="base_link"/>
    <child link="base_logo_front"/>
  </joint>
  <!-- LOGO ROBOTNIK REAR -->
  <link name="base_logo_rear">
    <visual>
      <origin rpy="0 0 0" xyz="0 0 0"/>
      <geometry>
        <mesh filename="package://robotnik_description/meshes/bases/robotnik_logo_chasis.stl"/>
      </geometry>
      <material name="darkgrey">
        <color rgba="0.5 0.5 0.5 1"/>
      </material>
    </visual>
  </link>
  <joint name="base_logo_rear_joint" type="fixed">
    <origin rpy="0 0 1.5707963267948966" xyz="-0.345 0.0 0.0"/>
    <parent link="base_link"/>
    <child link="base_logo_rear"/>
  </joint>
  <!-- DOCKING CONTACT -->
  <link name="base_docking_contact"/>
  <joint name="base_docking_joint" type="fixed">
    <origin rpy="0 0 0" xyz="0.35 0 0.09"/>
    <parent link="base_link"/>
    <child link="base_docking_contact"/>
  </joint>
  <joint name="front_right_wheel_joint" type="continuous">
    <parent link="base_link"/>
    <child link="front_right_wheel_link"/>
    <origin rpy="0 0 0" xyz="0.21528 -0.259 0.0"/>
    <limit effort="100000" velocity="100"/>
    <axis xyz="0 1 0"/>
  </joint>
  <link name="front_right_wheel_link">
    <visual>
      <origin rpy="0 0 0" xyz="0 0 0"/>
      <geometry>
        <mesh filename="package://robotnik_description/meshes/wheels/mecanum_wheel/kairos_mecanum_wheel_2.dae"/>
      </geometry>
      <material name="darkgrey">
        <color rgba="0.2 0.2 0.2 1"/>
      </material>
    </visual>
    <collision>
      <origin rpy="0 0 0" xyz="0 0 0"/>
      <geometry>
        <sphere radius="0.127"/>
      </geometry>
    </collision>
    <inertial>
      <mass value="6.5"/>
      <origin xyz="0 0 0"/>
      <inertia ixx="0.0303095" ixy="0" ixz="0" iyy="0.05241925" iyz="0" izz="0.0303095"/>
    </inertial>
  </link>
  <gazebo reference="front_right_wheel_link">
    <collision>
      <surface>
        <friction>
          <ode>
            <mu>1.0</mu>
            <mu2>0.0</mu2>
            <fdir1 gz:expressed_in="base_footprint">1 1 0</fdir1>
          </ode>
        </friction>
      </surface>
    </collision>
  </gazebo>
  <joint name="front_left_wheel_joint" type="continuous">
    <parent link="base_link"/>
    <child link="front_left_wheel_link"/>
    <origin rpy="0 0 0" xyz="0.21528 0.259 0.0"/>
    <limit effort="100000" velocity="100"/>
    <axis xyz="0 1 0"/>
  </joint>
  <link name="front_left_wheel_link">
    <visual>
      <origin rpy="0 0 0" xyz="0 0 0"/>
      <geometry>
        <mesh filename="package://robotnik_description/meshes/wheels/mecanum_wheel/kairos_mecanum_wheel_1.dae"/>
      </geometry>
      <material name="darkgrey">
        <color rgba="0.2 0.2 0.2 1"/>
      </material>
    </visual>
    <collision>
      <origin rpy="0 0 0" xyz="0 0 0"/>
      <geometry>
        <sphere radius="0.127"/>
      </geometry>
    </collision>
    <inertial>
      <mass value="6.5"/>
      <origin xyz="0 0 0"/>
      <inertia ixx="0.0303095" ixy="0" ixz="0" iyy="0.05241925" iyz="0" izz="0.0303095"/>
    </inertial>
  </link>
  <gazebo reference="front_left_wheel_link">
    <collision>
      <surface>
        <friction>
          <ode>
            <mu>1.0</mu>
            <mu2>0.0</mu2>
            <fdir1 gz:expressed_in="base_footprint">1 -1 0</fdir1>
          </ode>
        </friction>
      </surface>
    </collision>
  </gazebo>
  <joint name="back_left_wheel_joint" type="continuous">
    <parent link="base_link"/>
    <child link="back_left_wheel_link"/>
    <origin rpy="0 0 0" xyz="-0.21528 0.259 0.0"/>
    <limit effort="100000" velocity="100"/>
    <axis xyz="0 1 0"/>
  </joint>
  <link name="back_left_wheel_link">
    <visual>
      <origin rpy="0 0 0" xyz="0 0 0"/>
      <geometry>
        <mesh filename="package://robotnik_description/meshes/wheels/mecanum_wheel/kairos_mecanum_wheel_2.dae"/>
      </geometry>
      <material name="darkgrey">
        <color rgba="0.2 0.2 0.2 1"/>
      </material>
    </visual>
    <collision>
      <origin rpy="0 0 0" xyz="0 0 0"/>
      <geometry>
        <sphere radius="0.127"/>
      </geometry>
    </collision>
    <inertial>
      <mass value="6.5"/>
      <origin xyz="0 0 0"/>
      <inertia ixx="0.0303095" ixy="0" ixz="0" iyy="0.05241925" iyz="0" izz="0.0303095"/>
    </inertial>
  </link>
  <gazebo reference="back_left_wheel_link">
    <collision>
      <surface>
        <friction>
          <ode>
            <mu>1.0</mu>
            <mu2>0.0</mu2>
            <fdir1 gz:expressed_in="base_footprint">1 1 0</fdir1>
          </ode>
        </friction>
      </surface>
    </collision>
  </gazebo>
  <joint name="back_right_wheel_joint" type="continuous">
    <parent link="base_link"/>
    <child link="back_right_wheel_link"/>
    <origin rpy="0 0 0" xyz="-0.21528 -0.259 0.0"/>
    <limit effort="100000" velocity="100"/>
    <axis xyz="0 1 0"/>
  </joint>
  <link name="back_right_wheel_link">
    <visual>
      <origin rpy="0 0 0" xyz="0 0 0"/>
      <geometry>
        <mesh filename="package://robotnik_description/meshes/wheels/mecanum_wheel/kairos_mecanum_wheel_1.dae"/>
      </geometry>
      <material name="darkgrey">
        <color rgba="0.2 0.2 0.2 1"/>
      </material>
    </visual>
    <collision>
      <origin rpy="0 0 0" xyz="0 0 0"/>
      <geometry>
        <sphere radius="0.127"/>
      </geometry>
    </collision>
    <inertial>
      <mass value="6.5"/>
      <origin xyz="0 0 0"/>
      <inertia ixx="0.0303095" ixy="0" ixz="0" iyy="0.05241925" iyz="0" izz="0.0303095"/>
    </inertial>
  </link>
  <gazebo reference="back_right_wheel_link">
    <collision>
      <surface>
        <friction>
          <ode>
            <mu>1.0</mu>
            <mu2>0.0</mu2>
            <fdir1 gz:expressed_in="base_footprint">1 -1 0</fdir1>
          </ode>
        </friction>
      </surface>
    </collision>
  </gazebo>
  <gazebo>
    <plugin filename="gz_ros2_control-system" name="gz_ros2_control::GazeboSimROS2ControlPlugin">
      <robot_param>robot_description</robot_param>
      <robot_param_node>robot_state_publisher</robot_param_node>
      <parameters>/home/developer/ws/src/beluga_demo/common/beluga_demo_description/config/kairos_controller_params.yaml</parameters>
      <ros>
        <namespace>/</namespace>
      </ros> 
    </plugin>
  </gazebo>
  <ros2_control name="IgnitionSystem" type="system">
    <hardware>
      <plugin>gz_ros2_control/GazeboSimSystem</plugin>
    </hardware>
    <joint name="front_left_wheel_joint">
      <command_interface name="velocity">
        <param name="min">-10</param>
        <param name="max">10</param>
      </command_interface>
      <state_interface name="position"/>
      <state_interface name="velocity"/>
      <state_interface name="effort"/>
    </joint>
    <joint name="front_right_wheel_joint">
      <command_interface name="velocity">
        <param name="min">-10</param>
        <param name="max">10</param>
      </command_interface>
      <state_interface name="position"/>
      <state_interface name="velocity"/>
      <state_interface name="effort"/>
    </joint>
    <joint name="back_left_wheel_joint">
      <command_interface name="velocity">
        <param name="min">-20</param>
        <param name="max">20</param>
      </command_interface>
      <state_interface name="position"/>
      <state_interface name="velocity"/>
      <state_interface name="effort"/>
    </joint>
    <joint name="back_right_wheel_joint">
      <command_interface name="velocity">
        <param name="min">-20</param>
        <param name="max">20</param>
      </command_interface>
      <state_interface name="position"/>
      <state_interface name="velocity"/>
      <state_interface name="effort"/>
    </joint>
  </ros2_control>
  <joint name="imu_base_joint" type="fixed">
    <origin rpy="0 0 0" xyz="0.127 -0.129 0.212"/>
    <parent link="base_link"/>
    <child link="imu_base_link"/>
  </joint>
  <link name="imu_base_link">
    <inertial>
      <origin rpy="0 0 0" xyz="0.0 0 0.01"/>
      <mass value="0.05"/>
      <inertia ixx="3.3333333333333337e-06" ixy="0" ixz="0" iyy="3.3333333333333337e-06" iyz="0" izz="3.3333333333333337e-06"/>
    </inertial>
    <visual>
      <origin rpy="0 0 0" xyz="0 0 0"/>
      <material name="vectornav_imu_color">
        <color rgba="1 0 0 1"/>
      </material>
      <geometry>
        <mesh filename="package://robotnik_sensors/meshes/imu/vectornav_vn100.stl"/>
      </geometry>
    </visual>
    <collision>
      <origin rpy="0 0 0" xyz="0 0 0.0045"/>
      <geometry>
        <box size="0.036 0.037 0.009"/>
      </geometry>
    </collision>
  </link>
  <joint name="imu_joint" type="fixed">
    <axis xyz="1 0 0"/>
    <origin xyz="-0.00745 0.0 0.0088"/>
    <parent link="imu_base_link"/>
    <child link="imu_link"/>
  </joint>
  <link name="imu_link"/>
  <gazebo reference="imu_link">
    <gravity>true</gravity>
    <sensor name="imu_sensor" type="imu">
      <always_on>true</always_on>
      <update_rate>200.0</update_rate>
      <visualize>true</visualize>
      <imu>
        <orientation>
          <x>
            <noise type="gaussian">
              <mean>0.0</mean>
              <stddev>2e-3</stddev>
            </noise>
          </x>
          <y>
            <noise type="gaussian">
              <mean>0.0</mean>
              <stddev>2e-3</stddev>
            </noise>
          </y>
          <z>
            <noise type="gaussian">
              <mean>0.0</mean>
              <stddev>2e-3</stddev>
            </noise>
          </z>
        </orientation>
        <angular_velocity>
          <x>
            <noise type="gaussian">
              <mean>0.0</mean>
              <stddev>2e-4</stddev>
            </noise>
          </x>
          <y>
            <noise type="gaussian">
              <mean>0.0</mean>
              <stddev>2e-4</stddev>
            </noise>
          </y>
          <z>
            <noise type="gaussian">
              <mean>0.0</mean>
              <stddev>2e-4</stddev>
            </noise>
          </z>
        </angular_velocity>
        <linear_acceleration>
          <x>
            <noise type="gaussian">
              <mean>0.0</mean>
              <stddev>1.7e-2</stddev>
            </noise>
          </x>
          <y>
            <noise type="gaussian">
              <mean>0.0</mean>
              <stddev>1.7e-2</stddev>
            </noise>
          </y>
          <z>
            <noise type="gaussian">
              <mean>0.0</mean>
              <stddev>1.7e-2</stddev>
            </noise>
          </z>
        </linear_acceleration>
        <orientation_enabled>true</orientation_enabled>
        <angular_velocity_enabled>
              true
            </angular_velocity_enabled>
        <linear_acceleration_enabled>
              true
            </linear_acceleration_enabled>
      </imu>
      <topic>/imu/data</topic>
      <gz_frame_id>imu_link</gz_frame_id>
    </sensor>
  </gazebo>
  <gazebo reference="imu_base_link">
    <material>Gazebo/Red</material>
  </gazebo>
  <joint name="front_laser_base_joint" type="fixed">
    <origin rpy="0 -3.141592653589793 2.356194490192345" xyz="0.2865 -0.20894 0.2973"/>
    <parent link="base_link"/>
    <child link="front_laser_base_link"/>
  </joint>
  <link name="front_laser_base_link">
    <visual>
      <origin rpy="-1.5707963267948966 0 0" xyz="0 0 0"/>
      <geometry>
        <mesh filename="package://robotnik_sensors/meshes/2d_lidar/sick/s300.dae"/>
      </geometry>
    </visual>
    <collision>
      <origin rpy="-1.5707963267948966 0 0" xyz="0 0 0"/>
      <geometry>
        <mesh filename="package://robotnik_sensors/meshes/2d_lidar/sick/s300.dae"/>
      </geometry>
    </collision>
    <inertial>
      <mass value="0.25"/>
      <origin rpy="0 0 0" xyz="-0.0017 0 0.042875"/>
      <inertia ixx="0.00022818880208333336" ixy="0" ixz="0" iyy="0.0002307096354166667" iyz="0" izz="0.0001525208333333333"/>
    </inertial>
  </link>
  <joint name="front_laser_joint" type="fixed">
    <origin rpy="0 0 0" xyz="0.0 0 0.116"/>
    <parent link="front_laser_base_link"/>
    <child link="front_laser_link"/>
  </joint>
  <link name="front_laser_link"/>
  <gazebo reference="front_laser_link">
    <sensor name="front_laser" type="gpu_lidar">
      <pose>0 0 0 0 0 0</pose>
      <always_on>true</always_on>
      <visualize>true</visualize>
      <update_rate>25.0</update_rate>
      <lidar>
        <scan>
          <horizontal>
            <samples>270</samples>
            <resolution>1</resolution>
            <min_angle>-2.2689280275926285</min_angle>
            <max_angle>2.2689280275926285</max_angle>
          </horizontal>
        </scan>
        <range>
          <min>0.05</min>
          <max>10.0</max>
          <resolution>0.00575</resolution>
        </range>
        <noise>
          <type>gaussian</type>
          <mean>0.0</mean>
          <stddev>0.03</stddev>
        </noise>
      </lidar>
      <topic>/front_laser/scan</topic>
      <gz_frame_id>front_laser_link</gz_frame_id>
    </sensor>
  </gazebo>
  
  <joint name="rear_laser_base_joint" type="fixed">
    <origin rpy="0 -3.141592653589793 -0.7853981633974483" xyz="-0.2865 0.20894 0.2973"/>
    <parent link="base_link"/>
    <child link="rear_laser_base_link"/>
  </joint>
  <link name="rear_laser_base_link">
    <visual>
      <origin rpy="-1.5707963267948966 0 0" xyz="0 0 0"/>
      <geometry>
        <mesh filename="package://robotnik_sensors/meshes/2d_lidar/sick/s300.dae"/>
      </geometry>
    </visual>
    <collision>
      <origin rpy="-1.5707963267948966 0 0" xyz="0 0 0"/>
      <geometry>
        <mesh filename="package://robotnik_sensors/meshes/2d_lidar/sick/s300.dae"/>
      </geometry>
    </collision>
    <inertial>
      <mass value="0.25"/>
      <origin rpy="0 0 0" xyz="-0.0017 0 0.042875"/>
      <inertia ixx="0.00022818880208333336" ixy="0" ixz="0" iyy="0.0002307096354166667" iyz="0" izz="0.0001525208333333333"/>
    </inertial>
  </link>
  <joint name="rear_laser_joint" type="fixed">
    <origin rpy="0 0 0" xyz="0.0 0 0.116"/>
    <parent link="rear_laser_base_link"/>
    <child link="rear_laser_link"/>
  </joint>
  <link name="rear_laser_link"/>
  <gazebo reference="rear_laser_link">
    <sensor name="rear_laser" type="gpu_lidar">
      <pose>0 0 0 0 0 0</pose>
      <visualize>false</visualize>
      <update_rate>25.0</update_rate>
      <lidar>
        <scan>
          <horizontal>
            <samples>270</samples>
            <resolution>1</resolution>
            <min_angle>-2.2689280275926285</min_angle>
            <max_angle>2.2689280275926285</max_angle>
          </horizontal>
        </scan>
        <range>
          <min>0.05</min>
          <max>10.0</max>
          <resolution>0.00575</resolution>
        </range>
        <noise>
          <type>gaussian</type>
          <mean>0.0</mean>
          <stddev>0.03</stddev>
        </noise>
      </lidar>
      <topic>/rear_laser/scan</topic>
      <gz_frame_id>rear_laser_link</gz_frame_id>
    </sensor>
  </gazebo>
  <joint name="front_rgbd_camera_base_joint" type="fixed">
    <origin rpy="0 0 0" xyz="0.35850 0.0 0.25062"/>
    <parent link="base_link"/>
    <child link="front_rgbd_camera_base_link"/>
  </joint>
  <link name="front_rgbd_camera_base_link"/>
  <!-- camera body, with origin at bottom screw mount -->
  <joint name="front_rgbd_camera_joint" type="fixed">
    <parent link="front_rgbd_camera_base_link"/>
    <child link="front_rgbd_camera_link"/>
    <origin rpy="0 0 0" xyz="0.01 0.02 0"/>
    <child link="front_rgbd_camera_link"/>
  </joint>
  <link name="front_rgbd_camera_link">
    <!-- camera link is aligned with the infrared sensor 1 that is "in the middle of the camera", not the one in the edge -->
    <visual>
      <origin rpy="1.5707963267948966 0 1.5707963267948966" xyz="0.0149 -0.0175 0"/>
      <geometry>
        <!-- <box size="${d435_cam_width} ${d435_cam_height} ${d435_cam_depth}"/> -->
        <mesh filename="package://robotnik_sensors/meshes/depth/intel_realsense_d435/intel_d435_color.dae"/>
      </geometry>
    </visual>
    <collision>
      <origin rpy="0 0 0" xyz="0 -0.0175 0"/>
      <geometry>
        <box size="0.02505 0.09 0.025"/>
      </geometry>
    </collision>
    <inertial>
      <origin rpy="0 0 0" xyz="0.0025 -0.015 0.0"/>
      <mass value="0.1"/>
      <inertia ixx="7.270833333333333e-05" ixy="0" ixz="0" iyy="1.041666666666667e-05" iyz="0" izz="7.270833333333333e-05"/>
    </inertial>
  </link>
  <!-- Use the nominal extrinsics between camera frames if the calibrated extrinsics aren't being published. e.g. running the device in simulation  -->
  <!-- camera depth joints and links -->
  <joint name="front_rgbd_camera_depth_joint" type="fixed">
    <origin rpy="0 0 0" xyz="0 0 0"/>
    <parent link="front_rgbd_camera_link"/>
    <child link="front_rgbd_camera_depth_frame"/>
  </joint>
  <link name="front_rgbd_camera_depth_frame"/>
  <joint name="front_rgbd_camera_depth_optical_joint" type="fixed">
    <origin rpy="-1.5707963267948966 0 -1.5707963267948966" xyz="0 0 0"/>
    <parent link="front_rgbd_camera_depth_frame"/>
    <child link="front_rgbd_camera_depth_optical_frame"/>
  </joint>
  <link name="front_rgbd_camera_depth_optical_frame"/>
  <!-- camera left IR joints and links -->
  <joint name="front_rgbd_camera_infra1_joint" type="fixed">
    <origin rpy="0 0 0" xyz="0 0.0 0"/>
    <parent link="front_rgbd_camera_link"/>
    <child link="front_rgbd_camera_infra1_frame"/>
  </joint>
  <link name="front_rgbd_camera_infra1_frame"/>
  <joint name="front_rgbd_camera_infra1_optical_joint" type="fixed">
    <origin rpy="-1.5707963267948966 0 -1.5707963267948966" xyz="0 0 0"/>
    <parent link="front_rgbd_camera_infra1_frame"/>
    <child link="front_rgbd_camera_infra1_optical_frame"/>
  </joint>
  <link name="front_rgbd_camera_infra1_optical_frame"/>
  <!-- camera right IR joints and links -->
  <joint name="front_rgbd_camera_infra2_joint" type="fixed">
    <origin rpy="0 0 0" xyz="0 -0.05 0"/>
    <parent link="front_rgbd_camera_link"/>
    <child link="front_rgbd_camera_infra2_frame"/>
  </joint>
  <link name="front_rgbd_camera_infra2_frame"/>
  <joint name="front_rgbd_camera_infra2_optical_joint" type="fixed">
    <origin rpy="-1.5707963267948966 0 -1.5707963267948966" xyz="0 0 0"/>
    <parent link="front_rgbd_camera_infra2_frame"/>
    <child link="front_rgbd_camera_infra2_optical_frame"/>
  </joint>
  <link name="front_rgbd_camera_infra2_optical_frame"/>
  <!-- camera color joints and links -->
  <joint name="front_rgbd_camera_color_joint" type="fixed">
    <origin rpy="0 0 0" xyz="0 0.015 0"/>
    <parent link="front_rgbd_camera_link"/>
    <child link="front_rgbd_camera_color_frame"/>
  </joint>
  <link name="front_rgbd_camera_color_frame"/>
  <joint name="front_rgbd_camera_color_optical_joint" type="fixed">
    <origin rpy="-1.5707963267948966 0 -1.5707963267948966" xyz="0 0 0"/>
    <parent link="front_rgbd_camera_color_frame"/>
    <child link="front_rgbd_camera_color_optical_frame"/>
  </joint>
  <link name="front_rgbd_camera_color_optical_frame"/>
  <gazebo reference="front_rgbd_camera_color_frame">
    <sensor name="front_camera_color" type="camera">
      <camera name="front_camera_color">
        <horizontal_fov>
              1.2112585008840648
            </horizontal_fov>
        <vertical_fov>
              0.6806784082777885
            </vertical_fov>
        <image>
          <width>1920</width>
          <height>1080</height>
          <format>RGB_INT8</format>
        </image>
        <clip>
          <near>0.1</near>
          <far>100</far>
        </clip>
        <noise>
          <type>gaussian</type>
          <mean>0.0</mean>
          <stddev>0.05</stddev>
        </noise>
      </camera>
      <always_on>1</always_on>
      <update_rate>30</update_rate>
      <visualize>false</visualize>
      <topic>
            /front_camera_color/color/image_raw
          </topic>
      <gz_frame_id>front_rgbd_camera_color_optical_frame</gz_frame_id>
      <camera_info_topic>
            /front_camera_color/color/camera_info
          </camera_info_topic>
    </sensor>
  </gazebo>
</robot>
